Workbook

Sheet 00_HOME
A1: SAMI-NONAK POLBENG — GOOGLE SHEET SISTEM
A2: Pusat aturan audit: kriteria mutu Permendiktisaintek 39/2025 dan pengendalian proses ISO 9001:2015
A4: KPI SISTEM | B4: Nilai | D4: ARSITEKTUR FINAL
A5: Unit aktif | B5: 24 | D5: 1. Google Sheet Sistem | E5: Konfigurasi, akun, unit, tupoksi, standar, pertanyaan default, workflow, dan template
A6: Fungsi unit | B6: 42 | D6: 2. Folder Tahun Audit | E6: Folder induk untuk seluruh audit pada satu tahun
A7: Klausul ISO proses | B7: 43 | D7: 3. Folder Unit-Tahun | E7: Nama folder: {unit_slug}_{audit_year}
A8: Butir audit default | B8: 250 | D8: 4. Google Sheet Unit-Tahun | E8: Seluruh transaksi auditee dan auditor disimpan pada file {unit_slug}_{audit_year}
A9: File transaksi pusat | B9: 0 | D9: 5. Folder EVIDENCE | E9: Berkas lampiran; metadata dan tautan berada pada tab 03_BUKTI
A10: Dasar mutu aktif | B10: Permendiktisaintek 39/2025 | D10: 6. Folder CETAK | E10: PDF instrumen, berita acara, laporan, temuan, tindak lanjut, dan verifikasi
A11: Pendekatan proses | B11: ISO 9001:2015 + Amd 1:2024 | D11: 7. Registry Sistem | E11: Hanya menyimpan ID, URL, unit, tahun, status, dan versi file audit
A12: PRINSIP RANCANGAN YANG WAJIB DIPERTAHANKAN
A13: A | B13: Sheet Sistem tidak menyimpan jawaban auditee, kertas kerja auditor, bukti, temuan, tindak lanjut, atau verifikasi.
A14: B | B14: Satu unit pada satu tahun audit menggunakan satu Google Sheet transaksi bernama {unit_slug}_{audit_year}.
A15: C | B15: Pertanyaan default berasal dari Sheet Sistem; salinan kerja dan seluruh revisinya berada pada file audit unit-tahun.
A16: D | B16: Instrumen tanpa perubahan auditor langsung diterbitkan; instrumen yang diubah wajib disetujui Verifikator/P4MP.
A17: E | B17: Kriteria audit memuat dua dimensi: regulasi/standar mutu dan klausul ISO untuk pengendalian proses bisnis.
A18: F | B18: Versi cetak disimpan sebagai PDF di folder CETAK dalam folder audit unit-tahun.
A20: Standar internal rancangan | B20: 25
A21: Fungsi unit terpetakan | B21: 42
A22: Butir matriks audit | B22: 250
A23: Status matriks | B23: COMPLETE — 2026-D1

Sheet 31_USER_SESSIONS
A1: session_id | B1: user_id | C1: token_hash | D1: session_status | E1: created_at | F1: expires_at | G1: last_activity_at | H1: revoked_at | I1: _created_at | J1: _created_by | K1: _updated_at | L1: _updated_by | M1: _row_version | N1: _deleted_at | O1: _deleted_by | P1: _spreadsheet_id | Q1: _audit_id
A2: c1b1802e-9c8b-4706-af9d-b8f61514c02c | B2: c73c3a59-8171-440d-b344-a86905adf9ae | C2: 5ec4931eed0d334914cfcaf7c5306bb4e27651ad618d274de8ef96f18560f85d | D2: REVOKED | E2: 46222.356 | F2: 46222.689 | G2: 46222.356 | H2: 46222.357 | I2: 46222.356 | J2: admin | K2: 46222.357 | L2: admin | M2: 4
A3: a4a27afc-b675-4520-b393-460eb9053a12 | B3: c73c3a59-8171-440d-b344-a86905adf9ae | C3: 659d9adb91d48b309534bdcf640889e614c959900d422585815d902ab74feb14 | D3: REVOKED | E3: 46222.357 | F3: 46222.691 | G3: 46222.362 | H3: 46222.365 | I3: 46222.357 | J3: admin | K3: 46222.365 | L3: SYSTEM | M3: 4
A4: f25e1dce-0784-4337-bd81-d6c40005f90f | B4: cfb22fc1-09e4-486e-a3aa-52ff8c9534a5 | C4: ce6ccf25b93e23f0ddeb33983f94b10f80b1213cbc4ae12b2cd9159b7b7c2766 | D4: REVOKED | E4: 46222.365 | F4: 46222.699 | G4: 46222.366 | H4: 46222.368 | I4: 46222.365 | J4: p3m-polbeng | K4: 46222.368 | L4: SYSTEM | M4: 3
A5: 47626f56-ca1d-40e7-b47a-02fccc7f8e40 | B5: 4769c65d-0d21-4afe-b675-847b63df9c64 | C5: f3e484e237c3bf54770183c4ed5bdb17be07d12b65dd1889bfc38bcb1490f5f3 | D5: REVOKED | E5: 46222.369 | F5: 46222.702 | G5: 46222.369 | H5: 46222.37 | I5: 46222.369 | J5: hardi-1234 | K5: 46222.37 | L5: SYSTEM | M5: 4
A6: 57b45546-4f5a-47c4-84cf-69ebc5d5713e | B6: c73c3a59-8171-440d-b344-a86905adf9ae | C6: 164fa8e7fb13b447c0db5926cda085e344d638b662353e861fe2f34f5e57878d | D6: REVOKED | E6: 46222.37 | F6: 46222.704 | G6: 46222.382 | H6: 46222.382 | I6: 46222.37 | J6: admin | K6: 46222.382 | L6: SYSTEM | M6: 6
A7: f2499049-2c9d-430b-9198-5b83ef0e0496 | B7: cfb22fc1-09e4-486e-a3aa-52ff8c9534a5 | C7: ba12eb61606c9d157022e62572dc667ba856dd43db176e61712025c5fd581c61 | D7: ACTIVE | E7: 46222.383 | F7: 46222.716 | G7: 46222.383 | I7: 46222.383 | J7: p3m-polbeng | K7: 46222.383 | L7: p3m-polbeng | M7: 2

Sheet 32_AUDIT_PERIODS
A1: period_id | B1: period_code | C1: period_name | D1: start_date | E1: end_date | F1: status | G1: _created_at | H1: _created_by | I1: _updated_at | J1: _updated_by | K1: _row_version | L1: _deleted_at | M1: _deleted_by | N1: _spreadsheet_id | O1: _audit_id
A2: c5cadec3-070e-469a-919b-6ff404b14afb | B2: PER-2026 | C2: Periode Audit 2026 | D2: 46023 | E2: 46387 | F2: ACTIVE | G2: 46222.353 | H2: SYSTEM | I2: 46222.353 | J2: SYSTEM | K2: 1

Sheet 33_NOTIFICATIONS
A1: notification_id | B1: rule_code | C1: recipient_user_id | D1: recipient_username | E1: subject | F1: message | G1: send_status | H1: scheduled_at | I1: sent_at | J1: _created_at | K1: _created_by | L1: _updated_at | M1: _updated_by | N1: _row_version | O1: _deleted_at | P1: _deleted_by | Q1: _spreadsheet_id | R1: _audit_id
A2: aa6a9c03-c19e-460f-b7b2-e706df59d4af | B2: NTF_AUDIT_PLANNED | C2: 4769c65d-0d21-4afe-b675-847b63df9c64 | D2: hardi-1234 | E2: Program audit AUD-2026-00001 telah dijadwalkan | F2: Audit AMI NA untuk Pusat Penelitian dan Pengabdian kepada Masyarakat dijadwalkan 2026-07-20–2026-07-21. | G2: SENT | H2: 46222.377 | I2: 46222.377 | J2: 46222.377 | K2: admin | L2: 46222.377 | M2: SYSTEM | N2: 2
A3: b1c6d2bb-42d1-4992-9937-fac491b665c1 | B3: NTF_AUDIT_PLANNED | C3: cfb22fc1-09e4-486e-a3aa-52ff8c9534a5 | D3: p3m-polbeng | E3: Program audit AUD-2026-00001 telah dijadwalkan | F3: Audit AMI NA untuk Pusat Penelitian dan Pengabdian kepada Masyarakat dijadwalkan 2026-07-20–2026-07-21. | G3: SENT | H3: 46222.377 | I3: 46222.377 | J3: 46222.377 | K3: admin | L3: 46222.378 | M3: SYSTEM | N3: 2
A4: daf56c56-92fb-4e58-bf3f-60991dc4ae06 | B4: NTF_INSTRUMENT_REVIEW | C4: 4769c65d-0d21-4afe-b675-847b63df9c64 | D4: hardi-1234 | E4: Instrumen menunggu telaah auditor | F4: Periksa seluruh pertanyaan default pada audit AUD-2026-00001. | G4: SENT | H4: 46222.379 | I4: 46222.38 | J4: 46222.379 | K4: admin | L4: 46222.38 | M4: SYSTEM | N4: 2

Sheet 34_SYSTEM_LOG
A1: log_id | B1: event_time | C1: actor_username | D1: action_code | E1: entity_type | F1: entity_id | G1: old_value_json | H1: new_value_json | I1: result | J1: _created_at | K1: _created_by | L1: _updated_at | M1: _updated_by | N1: _row_version | O1: _deleted_at | P1: _deleted_by | Q1: username | R1: role_code
A2: 3fb3e03e-abea-40d4-acf3-a47bf102751b | B2: 46222.353 | C2: SYSTEM | D2: SYSTEM_INITIALIZED | E2: SYSTEM | F2: 1J_32KxE3BsaXJVNxAk54A7XsLVvuV5PcV5UVaYZl68A | H2: {"ok":true,"checks":[{"name":"Google Sheet Sistem","ok":true,"detail":"SAMI-NONAK Polbeng - Google Sheet Sistem"},{"name":"Konfigurasi arsitektur","ok":true,"detail":"per unit dan tahun"},{"name":"Master utama","ok":true,"detail":"lengkap"},{"name":"Matriks audit","ok":true,"detail":"250 pertanyaan"},{"name":"Folder aplikasi","ok":true,"detail":"SAMI-NONAK Polbeng"},{"name":"Akun administrator","ok":true,"detail":"admin"},{"name":"Registry file audit","ok":true,"detail":"0 file terdaftar"},{"name":"Sheet teknis","ok":true,"detail":"lengkap"}],"timestamp":"2026-07-19T08:28:08+07:00","architecture":"PER_UNIT_YEAR_SPREADSHEET","repairs":["Konfigurasi arsitektur per-unit-per-tahun diperbarui"],"repairedAuditFiles":[],"rootFolderUrl":"https://drive.google.com/drive/folders/1bavSo7fYdE8p4rrMnGVAsGYmjLtWHCSs","backupFolderUrl":"https://drive.google.com/drive/folders/1JbEl9cRfltUxJUq13_HpCON4Y7uBZuTB","defaultAdmin":{"username":"admin","password":"Admin123"}} | I2: SUCCESS | J2: 46222.353 | K2: SYSTEM | L2: 46222.353 | M2: SYSTEM | N2: 1 | Q2: SYSTEM
A3: 01dc035a-7294-4c70-9de2-c5881692114e | B3: 46222.355 | C3: admin | D3: API_auth.login | E3: API | H3: {"error":"Username atau password tidak sesuai."} | I3: FAILED | J3: 46222.355 | K3: admin | L3: 46222.355 | M3: admin | N3: 1 | Q3: admin
A4: 8ad8b83a-96d7-4fc2-aa3b-a80f5a7db42b | B4: 46222.356 | C4: admin | D4: LOGIN | E4: USER | F4: c73c3a59-8171-440d-b344-a86905adf9ae | H4: {"username":"admin"} | I4: SUCCESS | J4: 46222.356 | K4: admin | L4: 46222.356 | M4: admin | N4: 1 | Q4: admin
A5: c92a33c5-7a7e-4a79-9926-94bf77df1a5a | B5: 46222.357 | C5: admin | D5: UPDATE | E5: USERS | F5: c73c3a59-8171-440d-b344-a86905adf9ae | G5: {"_sheet_row":3,"user_id":"c73c3a59-8171-440d-b344-a86905adf9ae","username":"admin","password":"[REDACTED]","full_name":"Administrator SAMI-NONAK","unit_id":"UNIT-POLBENG","role_codes":"SUPER_ADMIN","status":"ACTIVE","must_change_password":true,"failed_login_count":0,"locked_until":"","last_login_at":"2026-07-19T08:32:07+07:00","created_at":"2026-07-19T08:27:53+07:00","updated_at":"2026-07-19T08:32:09+07:00","notes":"Akun awal dibuat oleh initSystem()","_created_at":"2026-07-19T08:27:53+07:00","_created_by":"SYSTEM","_updated_at":"2026-07-19T08:32:09+07:00","_updated_by":"admin","_row_version":3,"_deleted_at":"","_deleted_by":"","_spreadsheet_id":"1J_32KxE3BsaXJVNxAk54A7XsLVvuV5PcV5UVaYZl68A","_audit_id":""} | H5: {"_sheet_row":3,"user_id":"c73c3a59-8171-440d-b344-a86905adf9ae","username":"admin","password":"[REDACTED]","full_name":"Administrator SAMI-NONAK","unit_id":"UNIT-POLBENG","role_codes":"SUPER_ADMIN","status":"ACTIVE","must_change_password":false,"failed_login_count":0,"locked_until":"","last_login_at":"2026-07-19T08:32:07+07:00","created_at":"2026-07-19T08:27:53+07:00","updated_at":"2026-07-19T08:33:32+07:00","notes":"Akun awal dibuat oleh initSystem()","_created_at":"2026-07-19T08:27:53+07:00","_created_by":"SYSTEM","_updated_at":"2026-07-19T08:33:32+07:00","_updated_by":"admin","_row_version":4,"_deleted_at":"","_deleted_by":"","_spreadsheet_id":"1J_32KxE3BsaXJVNxAk54A7XsLVvuV5PcV5UVaYZl68A","_audit_id":""} | I5: SUCCESS | J5: 46222.357 | K5: admin | L5: 46222.357 | M5: admin | N5: 1 | Q5: admin
A6: 414854ec-6e9a-4e79-b2d4-69df9eb88d15 | B6: 46222.357 | C6: admin | D6: API_auth.changePassword | E6: API | H6: {"error":"Password lama tidak sesuai."} | I6: FAILED | J6: 46222.357 | K6: admin | L6: 46222.357 | M6: admin | N6: 1 | Q6: admin
A7: 583bb483-a729-4db4-8425-7e8e692d6f97 | B7: 46222.357 | C7: admin | D7: UPDATE | E7: USERS | F7: c73c3a59-8171-440d-b344-a86905adf9ae | G7: {"_sheet_row":3,"user_id":"c73c3a59-8171-440d-b344-a86905adf9ae","username":"admin","password":"[REDACTED]","full_name":"Administrator SAMI-NONAK","unit_id":"UNIT-POLBENG","role_codes":"SUPER_ADMIN","status":"ACTIVE","must_change_password":false,"failed_login_count":0,"locked_until":"","last_login_at":"2026-07-19T08:32:07+07:00","created_at":"2026-07-19T08:27:53+07:00","updated_at":"2026-07-19T08:33:32+07:00","notes":"Akun awal dibuat oleh initSystem()","_created_at":"2026-07-19T08:27:53+07:00","_created_by":"SYSTEM","_updated_at":"2026-07-19T08:33:32+07:00","_updated_by":"admin","_row_version":4,"_deleted_at":"","_deleted_by":"","_spreadsheet_id":"1J_32KxE3BsaXJVNxAk54A7XsLVvuV5PcV5UVaYZl68A","_audit_id":""} | H7: {"_sheet_row":3,"user_id":"c73c3a59-8171-440d-b344-a86905adf9ae","username":"admin","password":"[REDACTED]","full_name":"Administrator SAMI-NONAK","unit_id":"UNIT-POLBENG","role_codes":"SUPER_ADMIN","status":"ACTIVE","must_change_password":false,"failed_login_count":0,"locked_until":"","last_login_at":"2026-07-19T08:32:07+07:00","created_at":"2026-07-19T08:27:53+07:00","updated_at":"2026-07-19T08:33:45+07:00","notes":"Akun awal dibuat oleh initSystem()","_created_at":"2026-07-19T08:27:53+07:00","_created_by":"SYSTEM","_updated_at":"2026-07-19T08:33:45+07:00","_updated_by":"admin","_row_version":5,"_deleted_at":"","_deleted_by":"","_spreadsheet_id":"1J_32KxE3BsaXJVNxAk54A7XsLVvuV5PcV5UVaYZl68A","_audit_id":""} | I7: SUCCESS | J7: 46222.357 | K7: admin | L7: 46222.357 | M7: admin | N7: 1 | Q7: admin
A8: 65a54120-bf3a-416a-8d10-3e066ce0f4ee | B8: 46222.357 | C8: admin | D8: LOGIN | E8: USER | F8: c73c3a59-8171-440d-b344-a86905adf9ae | H8: {"username":"admin"} | I8: SUCCESS | J8: 46222.357 | K8: admin | L8: 46222.357 | M8: admin | N8: 1 | Q8: admin
A9: 5227bce6-f750-4595-b991-3f00f505a377 | B9: 46222.36 | C9: admin | D9: CREATE | E9: USERS | F9: cfb22fc1-09e4-486e-a3aa-52ff8c9534a5 | H9: {"_sheet_row":4,"user_id":"cfb22fc1-09e4-486e-a3aa-52ff8c9534a5","username":"p3m-polbeng","password":"[REDACTED]","full_name":"P3M","unit_id":"UNIT-P3M","role_codes":"KEPALA_UNIT","status":"ACTIVE","must_change_password":false,"failed_login_count":0,"locked_until":"","last_login_at":"","created_at":"2026-07-19T08:38:52+07:00","updated_at":"2026-07-19T08:38:52+07:00","notes":"","_created_at":"2026-07-19T08:38:52+07:00","_created_by":"admin","_updated_at":"2026-07-19T08:38:52+07:00","_updated_by":"admin","_row_version":1,"_deleted_at":"","_deleted_by":"","_spreadsheet_id":"1J_32KxE3BsaXJVNxAk54A7XsLVvuV5PcV5UVaYZl68A","_audit_id":""} | I9: SUCCESS | J9: 46222.36 | K9: admin | L9: 46222.36 | M9: admin | N9: 1 | Q9: admin
A10: b8b47ae8-4591-4bbb-bc81-d36a9b7c5384 | B10: 46222.362 | C10: admin | D10: UPDATE | E10: USERS | F10: cfb22fc1-09e4-486e-a3aa-52ff8c9534a5 | G10: {"_sheet_row":4,"user_id":"cfb22fc1-09e4-486e-a3aa-52ff8c9534a5","username":"p3m-polbeng","password":"[REDACTED]","full_name":"P3M","unit_id":"UNIT-P3M","role_codes":"KEPALA_UNIT","status":"ACTIVE","must_change_password":false,"failed_login_count":0,"locked_until":"","last_login_at":"","created_at":"2026-07-19T08:38:52+07:00","updated_at":"2026-07-19T08:38:52+07:00","notes":"","_created_at":"2026-07-19T08:38:52+07:00","_created_by":"admin","_updated_at":"2026-07-19T08:38:52+07:00","_updated_by":"admin","_row_version":1,"_deleted_at":"","_deleted_by":"","_spreadsheet_id":"1J_32KxE3BsaXJVNxAk54A7XsLVvuV5PcV5UVaYZl68A","_audit_id":""} | H10: {"_sheet_row":4,"user_id":"cfb22fc1-09e4-486e-a3aa-52ff8c9534a5","username":"p3m-polbeng","password":"[REDACTED]","full_name":"P3M","unit_id":"UNIT-P3M","role_codes":"AUDITEE|KEPALA_UNIT","status":"ACTIVE","must_change_password":false,"failed_login_count":0,"locked_until":"","last_login_at":"","created_at":"2026-07-19T08:38:52+07:00","updated_at":"2026-07-19T08:40:55+07:00","notes":"","_created_at":"2026-07-19T08:38:52+07:00","_created_by":"admin","_updated_at":"2026-07-19T08:40:55+07:00","_updated_by":"admin","_row_version":2,"_deleted_at":"","_deleted_by":"","_spreadsheet_id":"1J_32KxE3BsaXJVNxAk54A7XsLVvuV5PcV5UVaYZl68A","_audit_id":""} | I10: SUCCESS | J10: 46222.362 | K10: admin | L10: 46222.362 | M10: admin | N10: 1 | Q10: admin
A11: 8a22ee93-4f5a-4c1a-ac22-ab052f48a8ed | B11: 46222.363 | C11: admin | D11: CREATE | E11: USERS | F11: 4769c65d-0d21-4afe-b675-847b63df9c64 | H11: {"_sheet_row":5,"user_id":"4769c65d-0d21-4afe-b675-847b63df9c64","username":"hardi-1234","password":"[REDACTED]","full_name":"Dr. Hardiyanto, M.Si","unit_id":"UNIT-P4MP","role_codes":"KETUA_AUDITOR","status":"ACTIVE","must_change_password":false,"failed_login_count":0,"locked_until":"","last_login_at":"","created_at":"2026-07-19T08:42:30+07:00","updated_at":"2026-07-19T08:42:30+07:00","notes":"","_created_at":"2026-07-19T08:42:30+07:00","_created_by":"admin","_updated_at":"2026-07-19T08:42:30+07:00","_updated_by":"admin","_row_version":1,"_deleted_at":"","_deleted_by":"","_spreadsheet_id":"1J_32KxE3BsaXJVNxAk54A7XsLVvuV5PcV5UVaYZl68A","_audit_id":""} | I11: SUCCESS | J11: 46222.363 | K11: admin | L11: 46222.363 | M11: admin | N11: 1 | Q11: admin
A12: 2bb44553-cbf6-41f0-94eb-63f422cd22b2 | B12: 46222.366 | C12: p3m-polbeng | D12: LOGIN | E12: USER | F12: cfb22fc1-09e4-486e-a3aa-52ff8c9534a5 | H12: {"username":"p3m-polbeng"} | I12: SUCCESS | J12: 46222.366 | K12: p3m-polbeng | L12: 46222.366 | M12: p3m-polbeng | N12: 1 | Q12: p3m-polbeng
A13: bae3f6bd-1e69-48ea-9a60-f0dc70b535fe | B13: 46222.366 | C13: p3m-polbeng | D13: API_users.list | E13: API | H13: {"error":"Tidak berwenang melihat master pengguna."} | I13: FAILED | J13: 46222.366 | K13: p3m-polbeng | L13: 46222.366 | M13: p3m-polbeng | N13: 1 | Q13: p3m-polbeng
A14: d5354bbe-b962-4ec2-8ff1-abd420e56b69 | B14: 46222.368 | C14: hardi-polbeng | D14: API_auth.login | E14: API | H14: {"error":"Username atau password tidak sesuai."} | I14: FAILED | J14: 46222.368 | K14: hardi-polbeng | L14: 46222.368 | M14: hardi-polbeng | N14: 1 | Q14: hardi-polbeng
A15: 69e90d4a-c2fc-497f-8e3a-9ff65aff8cc8 | B15: 46222.369 | C15: hardi-1234 | D15: LOGIN | E15: USER | F15: 4769c65d-0d21-4afe-b675-847b63df9c64 | H15: {"username":"hardi-1234"} | I15: SUCCESS | J15: 46222.369 | K15: hardi-1234 | L15: 46222.369 | M15: hardi-1234 | N15: 1 | Q15: hardi-1234
A16: 48139838-43de-4a01-a343-7a2ab4c5c71c | B16: 46222.371 | C16: admin | D16: LOGIN | E16: USER | F16: c73c3a59-8171-440d-b344-a86905adf9ae | H16: {"username":"admin"} | I16: SUCCESS | J16: 46222.371 | K16: admin | L16: 46222.371 | M16: admin | N16: 1 | Q16: admin
A17: 03442889-ad68-4899-9e69-31e16ae82fd5 | B17: 46222.373 | C17: admin | D17: CREATE | E17: AUDIT_PROGRAMS | F17: 25f27b13-a0b0-46a7-b5f7-064277dbaf3f | H17: {"audit_id":"25f27b13-a0b0-46a7-b5f7-064277dbaf3f","audit_code":"AUD-2026-00001","period_id":"c5cadec3-070e-469a-919b-6ff404b14afb","audit_title":"AMI NA ","audit_type":"NON_AKADEMIK","unit_id":"UNIT-P3M","unit_name":"Pusat Penelitian dan Pengabdian kepada Masyarakat","unit_code":"P3M","risk_level":"LOW","planned_start":"2026-07-20","planned_end":"2026-07-21","status":"DRAFT","audit_status":"DRAFT","questionnaire_status":"NOT_PREPARED","questionnaire_published_at":"","manager_user_id":"c73c3a59-8171-440d-b344-a86905adf9ae","lead_auditor":"c73c3a59-8171-440d-b344-a86905adf9ae","auditee_head":"","notes":"","audit_year":"2026","audit_file_name":"p3m_2026","audit_folder_id":"1xKRMK3aqpGR9FFZ1DxohGZ4mHrf8M4zn","spreadsheet_id":"1c_FcPTNrSJdVK8S67Jrg9cDxq6_Umie8tnt0XTQn3Hw","created_at":"2026-07-19T08:57:18+07:00","_created_at":"2026-07-19T08:57:18+07:00","_created_by":"admin","_updated_at":"2026-07-19T08:57:18+07:00","_updated_by":"admin","_row_version":1,"_deleted_at":"","_deleted_by":""} | I17: SUCCESS | J17: 46222.373 | K17: admin | L17: 46222.373 | M17: admin | N17: 1 | Q17: admin
A18: dc3e28b6-144a-4cf3-b158-a770d5b27efa | B18: 46222.375 | C18: admin | D18: CREATE | E18: AUDIT_TEAMS | F18: effb0c4e-6ece-40c8-bb72-6c82918a5c8c | H18: {"audit_id":"25f27b13-a0b0-46a7-b5f7-064277dbaf3f","user_id":"4769c65d-0d21-4afe-b675-847b63df9c64","team_role":"LEAD","independence_status":"CLEARED","assigned_at":"2026-07-19T09:00:01+07:00","team_member_id":"effb0c4e-6ece-40c8-bb72-6c82918a5c8c","_spreadsheet_id":"1c_FcPTNrSJdVK8S67Jrg9cDxq6_Umie8tnt0XTQn3Hw","_audit_id":"25f27b13-a0b0-46a7-b5f7-064277dbaf3f","_created_at":"2026-07-19T09:00:01+07:00","_created_by":"admin","_row_version":1,"_deleted_at":"","_deleted_by":"","_updated_at":"2026-07-19T09:00:01+07:00","_updated_by":"admin","_sheet_row":2,"_tech_record_id":"effb0c4e-6ece-40c8-bb72-6c82918a5c8c"} | I18: SUCCESS | J18: 46222.375 | K18: admin | L18: 46222.375 | M18: admin | N18: 1 | Q18: admin
A19: 2e4252ef-1079-485b-8ea9-d27a2673b1a1 | B19: 46222.376 | C19: admin | D19: QUESTION_DRAFT_INITIALIZED | E19: AUDIT_PROGRAM | F19: 25f27b13-a0b0-46a7-b5f7-064277dbaf3f | H19: {"question_count":66} | I19: SUCCESS | J19: 46222.376 | K19: admin | L19: 46222.376 | M19: admin | N19: 1 | Q19: admin
A20: b770351e-0eb4-4a45-9483-9bb88ad26576 | B20: 46222.377 | C20: admin | D20: UPDATE | E20: AUDIT_PROGRAMS | F20: 25f27b13-a0b0-46a7-b5f7-064277dbaf3f | G20: {"_sheet_row":2,"audit_id":"25f27b13-a0b0-46a7-b5f7-064277dbaf3f","audit_year":2026,"unit_id":"UNIT-P3M","unit_name":"Pusat Penelitian dan Pengabdian kepada Masyarakat","audit_file_name":"p3m_2026","audit_folder_id":"1xKRMK3aqpGR9FFZ1DxohGZ4mHrf8M4zn","spreadsheet_id":"1c_FcPTNrSJdVK8S67Jrg9cDxq6_Umie8tnt0XTQn3Hw","audit_status":"DRAFT","planned_start":"2026-07-20T00:00:00+07:00","planned_end":"2026-07-21T00:00:00+07:00","lead_auditor":"4769c65d-0d21-4afe-b675-847b63df9c64","auditee_head":"","created_at":"2026-07-19T08:57:18+07:00","audit_code":"AUD-2026-00001","period_id":"c5cadec3-070e-469a-919b-6ff404b14afb","audit_title":"AMI NA ","audit_type":"NON_AKADEMIK","risk_level":"LOW","status":"DRAFT","manager_user_id":"4769c65d-0d21-4afe-b675-847b63df9c64","notes":"","_created_at":"2026-07-19T08:57:18+07:00","_created_by":"admin","_updated_at":"2026-07-19T09:01:40+07:00","_updated_by":"admin","_row_version":3,"_deleted_at":"","_deleted_by":"","unit_code":"P3M","questionnaire_status":"DRAFT","questionnaire_published_at":"","spreadsheet_url":"https://docs.google.com/spreadsheets/d/1c_FcPTNrSJdVK8S67Jrg9cDxq6_Umie8tnt0XTQn3Hw/edit","audit_folder_url":"https://drive.google.com/drive/folders/1xKRMK3aqpGR9FFZ1DxohGZ4mHrf8M4zn","evidence_folder_id":"1tbpVhkSnW46xiWLr-PNC6by__mRM-lkf","print_folder_id":"1m2D7XIvuDjXKMMG3mVmJeVL0KgcJIQ57","file_status":"CREATED","template_version":1,"_spreadsheet_id":"1c_FcPTNrSJdVK8S67Jrg9cDxq6_Umie8tnt0XTQn3Hw","_audit_id":"25f27b13-a0b0-46a7-b5f7-064277dbaf3f"} | H20: {"_sheet_row":2,"audit_id":"25f27b13-a0b0-46a7-b5f7-064277dbaf3f","audit_year":2026,"unit_id":"UNIT-P3M","unit_name":"Pusat Penelitian dan Pengabdian kepada Masyarakat","audit_file_name":"p3m_2026","audit_folder_id":"1xKRMK3aqpGR9FFZ1DxohGZ4mHrf8M4zn","spreadsheet_id":"1c_FcPTNrSJdVK8S67Jrg9cDxq6_Umie8tnt0XTQn3Hw","audit_status":"PLANNED","planned_start":"2026-07-20T00:00:00+07:00","planned_end":"2026-07-21T00:00:00+07:00","lead_auditor":"4769c65d-0d21-4afe-b675-847b63df9c64","auditee_head":"","created_at":"2026-07-19T08:57:18+07:00","audit_code":"AUD-2026-00001","period_id":"c5cadec3-070e-469a-919b-6ff404b14afb","audit_title":"AMI NA ","audit_type":"NON_AKADEMIK","risk_level":"LOW","status":"PLANNED","manager_user_id":"4769c65d-0d21-4afe-b675-847b63df9c64","notes":"","_created_at":"2026-07-19T08:57:18+07:00","_created_by":"admin","_updated_at":"2026-07-19T09:03:07+07:00","_updated_by":"admin","_row_version":4,"_deleted_at":"","_deleted_by":"","unit_code":"P3M","questionnaire_status":"DRAFT","questionnaire_published_at":"","spreadsheet_url":"https://docs.google.com/spreadsheets/d/1c_FcPTNrSJdVK8S67Jrg9cDxq6_Umie8tnt0XTQn3Hw/edit","audit_folder_url":"https://drive.google.com/drive/folders/1xKRMK3aqpGR9FFZ1DxohGZ4mHrf8M4zn","evidence_folder_id":"1tbpVhkSnW46xiWLr-PNC6by__mRM-lkf","print_folder_id":"1m2D7XIvuDjXKMMG3mVmJeVL0KgcJIQ57","file_status":"CREATED","template_version":1,"_spreadsheet_id":"1c_FcPTNrSJdVK8S67Jrg9cDxq6_Umie8tnt0XTQn3Hw","_audit_id":"25f27b13-a0b0-46a7-b5f7-064277dbaf3f"} | I20: SUCCESS | J20: 46222.377 | K20: admin | L20: 46222.377 | M20: admin | N20: 1 | Q20: admin
A21: a16edb68-6e72-42e4-9815-32c62dd14d58 | B21: 46222.378 | C21: admin | D21: WORKFLOW_APPROVE_PROGRAM | E21: AUDIT_PROGRAM | F21: 25f27b13-a0b0-46a7-b5f7-064277dbaf3f | G21: {"_sheet_row":2,"audit_id":"25f27b13-a0b0-46a7-b5f7-064277dbaf3f","audit_year":2026,"unit_id":"UNIT-P3M","unit_name":"Pusat Penelitian dan Pengabdian kepada Masyarakat","audit_file_name":"p3m_2026","audit_folder_id":"1xKRMK3aqpGR9FFZ1DxohGZ4mHrf8M4zn","spreadsheet_id":"1c_FcPTNrSJdVK8S67Jrg9cDxq6_Umie8tnt0XTQn3Hw","audit_status":"DRAFT","planned_start":"2026-07-20T00:00:00+07:00","planned_end":"2026-07-21T00:00:00+07:00","lead_auditor":"4769c65d-0d21-4afe-b675-847b63df9c64","auditee_head":"","created_at":"2026-07-19T08:57:18+07:00","audit_code":"AUD-2026-00001","period_id":"c5cadec3-070e-469a-919b-6ff404b14afb","audit_title":"AMI NA ","audit_type":"NON_AKADEMIK","risk_level":"LOW","status":"DRAFT","manager_user_id":"4769c65d-0d21-4afe-b675-847b63df9c64","notes":"","_created_at":"2026-07-19T08:57:18+07:00","_created_by":"admin","_updated_at":"2026-07-19T09:01:40+07:00","_updated_by":"admin","_row_version":3,"_deleted_at":"","_deleted_by":"","unit_code":"P3M","questionnaire_status":"DRAFT","questionnaire_published_at":"","spreadsheet_url":"https://docs.google.com/spreadsheets/d/1c_FcPTNrSJdVK8S67Jrg9cDxq6_Umie8tnt0XTQn3Hw/edit","audit_folder_url":"https://drive.google.com/drive/folders/1xKRMK3aqpGR9FFZ1DxohGZ4mHrf8M4zn","evidence_folder_id":"1tbpVhkSnW46xiWLr-PNC6by__mRM-lkf","print_folder_id":"1m2D7XIvuDjXKMMG3mVmJeVL0KgcJIQ57","file_status":"CREATED","template_version":1,"_spreadsheet_id":"1c_FcPTNrSJdVK8S67Jrg9cDxq6_Umie8tnt0XTQn3Hw","_audit_id":"25f27b13-a0b0-46a7-b5f7-064277dbaf3f"} | H21: {"_sheet_row":2,"audit_id":"25f27b13-a0b0-46a7-b5f7-064277dbaf3f","audit_year":2026,"unit_id":"UNIT-P3M","unit_name":"Pusat Penelitian dan Pengabdian kepada Masyarakat","audit_file_name":"p3m_2026","audit_folder_id":"1xKRMK3aqpGR9FFZ1DxohGZ4mHrf8M4zn","spreadsheet_id":"1c_FcPTNrSJdVK8S67Jrg9cDxq6_Umie8tnt0XTQn3Hw","audit_status":"PLANNED","planned_start":"2026-07-20T00:00:00+07:00","planned_end":"2026-07-21T00:00:00+07:00","lead_auditor":"4769c65d-0d21-4afe-b675-847b63df9c64","auditee_head":"","created_at":"2026-07-19T08:57:18+07:00","audit_code":"AUD-2026-00001","period_id":"c5cadec3-070e-469a-919b-6ff404b14afb","audit_title":"AMI NA ","audit_type":"NON_AKADEMIK","risk_level":"LOW","status":"PLANNED","manager_user_id":"4769c65d-0d21-4afe-b675-847b63df9c64","notes":"","_created_at":"2026-07-19T08:57:18+07:00","_created_by":"admin","_updated_at":"2026-07-19T09:03:07+07:00","_updated_by":"admin","_row_version":4,"_deleted_at":"","_deleted_by":"","unit_code":"P3M","questionnaire_status":"DRAFT","questionnaire_published_at":"","spreadsheet_url":"https://docs.google.com/spreadsheets/d/1c_FcPTNrSJdVK8S67Jrg9cDxq6_Umie8tnt0XTQn3Hw/edit","audit_folder_url":"https://drive.google.com/drive/folders/1xKRMK3aqpGR9FFZ1DxohGZ4mHrf8M4zn","evidence_folder_id":"1tbpVhkSnW46xiWLr-PNC6by__mRM-lkf","print_folder_id":"1m2D7XIvuDjXKMMG3mVmJeVL0KgcJIQ57","file_status":"CREATED","template_version":1,"_spreadsheet_id":"1c_FcPTNrSJdVK8S67Jrg9cDxq6_Umie8tnt0XTQn3Hw","_audit_id":"25f27b13-a0b0-46a7-b5f7-064277dbaf3f"} | I21: SUCCESS | J21: 46222.378 | K21: admin | L21: 46222.378 | M21: admin | N21: 1 | Q21: admin
A22: 6415f051-ca2d-47d1-843a-69a2f9ad2343 | B22: 46222.379 | C22: admin | D22: UPDATE | E22: AUDIT_PROGRAMS | F22: 25f27b13-a0b0-46a7-b5f7-064277dbaf3f | G22: {"_sheet_row":2,"audit_id":"25f27b13-a0b0-46a7-b5f7-064277dbaf3f","audit_year":2026,"unit_id":"UNIT-P3M","unit_name":"Pusat Penelitian dan Pengabdian kepada Masyarakat","audit_file_name":"p3m_2026","audit_folder_id":"1xKRMK3aqpGR9FFZ1DxohGZ4mHrf8M4zn","spreadsheet_id":"1c_FcPTNrSJdVK8S67Jrg9cDxq6_Umie8tnt0XTQn3Hw","audit_status":"PLANNED","planned_start":"2026-07-20T00:00:00+07:00","planned_end":"2026-07-21T00:00:00+07:00","lead_auditor":"4769c65d-0d21-4afe-b675-847b63df9c64","auditee_head":"","created_at":"2026-07-19T08:57:18+07:00","audit_code":"AUD-2026-00001","period_id":"c5cadec3-070e-469a-919b-6ff404b14afb","audit_title":"AMI NA ","audit_type":"NON_AKADEMIK","risk_level":"LOW","status":"PLANNED","manager_user_id":"4769c65d-0d21-4afe-b675-847b63df9c64","notes":"","_created_at":"2026-07-19T08:57:18+07:00","_created_by":"admin","_updated_at":"2026-07-19T09:03:07+07:00","_updated_by":"admin","_row_version":4,"_deleted_at":"","_deleted_by":"","unit_code":"P3M","questionnaire_status":"DRAFT","questionnaire_published_at":"","spreadsheet_url":"https://docs.google.com/spreadsheets/d/1c_FcPTNrSJdVK8S67Jrg9cDxq6_Umie8tnt0XTQn3Hw/edit","audit_folder_url":"https://drive.google.com/drive/folders/1xKRMK3aqpGR9FFZ1DxohGZ4mHrf8M4zn","evidence_folder_id":"1tbpVhkSnW46xiWLr-PNC6by__mRM-lkf","print_folder_id":"1m2D7XIvuDjXKMMG3mVmJeVL0KgcJIQ57","file_status":"CREATED","template_version":1,"_spreadsheet_id":"1c_FcPTNrSJdVK8S67Jrg9cDxq6_Umie8tnt0XTQn3Hw","_audit_id":"25f27b13-a0b0-46a7-b5f7-064277dbaf3f"} | H22: {"_sheet_row":2,"audit_id":"25f27b13-a0b0-46a7-b5f7-064277dbaf3f","audit_year":2026,"unit_id":"UNIT-P3M","unit_name":"Pusat Penelitian dan Pengabdian kepada Masyarakat","audit_file_name":"p3m_2026","audit_folder_id":"1xKRMK3aqpGR9FFZ1DxohGZ4mHrf8M4zn","spreadsheet_id":"1c_FcPTNrSJdVK8S67Jrg9cDxq6_Umie8tnt0XTQn3Hw","audit_status":"FILE_PREPARATION","planned_start":"2026-07-20T00:00:00+07:00","planned_end":"2026-07-21T00:00:00+07:00","lead_auditor":"4769c65d-0d21-4afe-b675-847b63df9c64","auditee_head":"","created_at":"2026-07-19T08:57:18+07:00","audit_code":"AUD-2026-00001","period_id":"c5cadec3-070e-469a-919b-6ff404b14afb","audit_title":"AMI NA ","audit_type":"NON_AKADEMIK","risk_level":"LOW","status":"FILE_PREPARATION","manager_user_id":"4769c65d-0d21-4afe-b675-847b63df9c64","notes":"","_created_at":"2026-07-19T08:57:18+07:00","_created_by":"admin","_updated_at":"2026-07-19T09:05:18+07:00","_updated_by":"admin","_row_version":5,"_deleted_at":"","_deleted_by":"","unit_code":"P3M","questionnaire_status":"DRAFT","questionnaire_published_at":"","spreadsheet_url":"https://docs.google.com/spreadsheets/d/1c_FcPTNrSJdVK8S67Jrg9cDxq6_Umie8tnt0XTQn3Hw/edit","audit_folder_url":"https://drive.google.com/drive/folders/1xKRMK3aqpGR9FFZ1DxohGZ4mHrf8M4zn","evidence_folder_id":"1tbpVhkSnW46xiWLr-PNC6by__mRM-lkf","print_folder_id":"1m2D7XIvuDjXKMMG3mVmJeVL0KgcJIQ57","file_status":"CREATED","template_version":1,"_spreadsheet_id":"1c_FcPTNrSJdVK8S67Jrg9cDxq6_Umie8tnt0XTQn3Hw","_audit_id":"25f27b13-a0b0-46a7-b5f7-064277dbaf3f"} | I22: SUCCESS | J22: 46222.379 | K22: admin | L22: 46222.379 | M22: admin | N22: 1 | Q22: admin
A23: 9660eb13-2e61-446c-9446-1a00d912bc7a | B23: 46222.379 | C23: admin | D23: WORKFLOW_PREPARE_AUDIT_FILE | E23: AUDIT_PROGRAM | F23: 25f27b13-a0b0-46a7-b5f7-064277dbaf3f | G23: {"_sheet_row":2,"audit_id":"25f27b13-a0b0-46a7-b5f7-064277dbaf3f","audit_year":2026,"unit_id":"UNIT-P3M","unit_name":"Pusat Penelitian dan Pengabdian kepada Masyarakat","audit_file_name":"p3m_2026","audit_folder_id":"1xKRMK3aqpGR9FFZ1DxohGZ4mHrf8M4zn","spreadsheet_id":"1c_FcPTNrSJdVK8S67Jrg9cDxq6_Umie8tnt0XTQn3Hw","audit_status":"PLANNED","planned_start":"2026-07-20T00:00:00+07:00","planned_end":"2026-07-21T00:00:00+07:00","lead_auditor":"4769c65d-0d21-4afe-b675-847b63df9c64","auditee_head":"","created_at":"2026-07-19T08:57:18+07:00","audit_code":"AUD-2026-00001","period_id":"c5cadec3-070e-469a-919b-6ff404b14afb","audit_title":"AMI NA ","audit_type":"NON_AKADEMIK","risk_level":"LOW","status":"PLANNED","manager_user_id":"4769c65d-0d21-4afe-b675-847b63df9c64","notes":"","_created_at":"2026-07-19T08:57:18+07:00","_created_by":"admin","_updated_at":"2026-07-19T09:03:07+07:00","_updated_by":"admin","_row_version":4,"_deleted_at":"","_deleted_by":"","unit_code":"P3M","questionnaire_status":"DRAFT","questionnaire_published_at":"","spreadsheet_url":"https://docs.google.com/spreadsheets/d/1c_FcPTNrSJdVK8S67Jrg9cDxq6_Umie8tnt0XTQn3Hw/edit","audit_folder_url":"https://drive.google.com/drive/folders/1xKRMK3aqpGR9FFZ1DxohGZ4mHrf8M4zn","evidence_folder_id":"1tbpVhkSnW46xiWLr-PNC6by__mRM-lkf","print_folder_id":"1m2D7XIvuDjXKMMG3mVmJeVL0KgcJIQ57","file_status":"CREATED","template_version":1,"_spreadsheet_id":"1c_FcPTNrSJdVK8S67Jrg9cDxq6_Umie8tnt0XTQn3Hw","_audit_id":"25f27b13-a0b0-46a7-b5f7-064277dbaf3f"} | H23: {"_sheet_row":2,"audit_id":"25f27b13-a0b0-46a7-b5f7-064277dbaf3f","audit_year":2026,"unit_id":"UNIT-P3M","unit_name":"Pusat Penelitian dan Pengabdian kepada Masyarakat","audit_file_name":"p3m_2026","audit_folder_id":"1xKRMK3aqpGR9FFZ1DxohGZ4mHrf8M4zn","spreadsheet_id":"1c_FcPTNrSJdVK8S67Jrg9cDxq6_Umie8tnt0XTQn3Hw","audit_status":"FILE_PREPARATION","planned_start":"2026-07-20T00:00:00+07:00","planned_end":"2026-07-21T00:00:00+07:00","lead_auditor":"4769c65d-0d21-4afe-b675-847b63df9c64","auditee_head":"","created_at":"2026-07-19T08:57:18+07:00","audit_code":"AUD-2026-00001","period_id":"c5cadec3-070e-469a-919b-6ff404b14afb","audit_title":"AMI NA ","audit_type":"NON_AKADEMIK","risk_level":"LOW","status":"FILE_PREPARATION","manager_user_id":"4769c65d-0d21-4afe-b675-847b63df9c64","notes":"","_created_at":"2026-07-19T08:57:18+07:00","_created_by":"admin","_updated_at":"2026-07-19T09:05:18+07:00","_updated_by":"admin","_row_version":5,"_deleted_at":"","_deleted_by":"","unit_code":"P3M","questionnaire_status":"DRAFT","questionnaire_published_at":"","spreadsheet_url":"https://docs.google.com/spreadsheets/d/1c_FcPTNrSJdVK8S67Jrg9cDxq6_Umie8tnt0XTQn3Hw/edit","audit_folder_url":"https://drive.google.com/drive/folders/1xKRMK3aqpGR9FFZ1DxohGZ4mHrf8M4zn","evidence_folder_id":"1tbpVhkSnW46xiWLr-PNC6by__mRM-lkf","print_folder_id":"1m2D7XIvuDjXKMMG3mVmJeVL0KgcJIQ57","file_status":"CREATED","template_version":1,"_spreadsheet_id":"1c_FcPTNrSJdVK8S67Jrg9cDxq6_Umie8tnt0XTQn3Hw","_audit_id":"25f27b13-a0b0-46a7-b5f7-064277dbaf3f"} | I23: SUCCESS | J23: 46222.379 | K23: admin | L23: 46222.379 | M23: admin | N23: 1 | Q23: admin
A24: 822947d9-377a-4eda-884c-e6e819c63c44 | B24: 46222.379 | C24: admin | D24: UPDATE | E24: AUDIT_PROGRAMS | F24: 25f27b13-a0b0-46a7-b5f7-064277dbaf3f | G24: {"_sheet_row":2,"audit_id":"25f27b13-a0b0-46a7-b5f7-064277dbaf3f","audit_year":2026,"unit_id":"UNIT-P3M","unit_name":"Pusat Penelitian dan Pengabdian kepada Masyarakat","audit_file_name":"p3m_2026","audit_folder_id":"1xKRMK3aqpGR9FFZ1DxohGZ4mHrf8M4zn","spreadsheet_id":"1c_FcPTNrSJdVK8S67Jrg9cDxq6_Umie8tnt0XTQn3Hw","audit_status":"FILE_PREPARATION","planned_start":"2026-07-20T00:00:00+07:00","planned_end":"2026-07-21T00:00:00+07:00","lead_auditor":"4769c65d-0d21-4afe-b675-847b63df9c64","auditee_head":"","created_at":"2026-07-19T08:57:18+07:00","audit_code":"AUD-2026-00001","period_id":"c5cadec3-070e-469a-919b-6ff404b14afb","audit_title":"AMI NA ","audit_type":"NON_AKADEMIK","risk_level":"LOW","status":"FILE_PREPARATION","manager_user_id":"4769c65d-0d21-4afe-b675-847b63df9c64","notes":"","_created_at":"2026-07-19T08:57:18+07:00","_created_by":"admin","_updated_at":"2026-07-19T09:05:18+07:00","_updated_by":"admin","_row_version":5,"_deleted_at":"","_deleted_by":"","unit_code":"P3M","questionnaire_status":"DRAFT","questionnaire_published_at":"","spreadsheet_url":"https://docs.google.com/spreadsheets/d/1c_FcPTNrSJdVK8S67Jrg9cDxq6_Umie8tnt0XTQn3Hw/edit","audit_folder_url":"https://drive.google.com/drive/folders/1xKRMK3aqpGR9FFZ1DxohGZ4mHrf8M4zn","evidence_folder_id":"1tbpVhkSnW46xiWLr-PNC6by__mRM-lkf","print_folder_id":"1m2D7XIvuDjXKMMG3mVmJeVL0KgcJIQ57","file_status":"ACTIVE","template_version":1,"_spreadsheet_id":"1c_FcPTNrSJdVK8S67Jrg9cDxq6_Umie8tnt0XTQn3Hw","_audit_id":"25f27b13-a0b0-46a7-b5f7-064277dbaf3f"} | H24: {"_sheet_row":2,"audit_id":"25f27b13-a0b0-46a7-b5f7-064277dbaf3f","audit_year":2026,"unit_id":"UNIT-P3M","unit_name":"Pusat Penelitian dan Pengabdian kepada Masyarakat","audit_file_name":"p3m_2026","audit_folder_id":"1xKRMK3aqpGR9FFZ1DxohGZ4mHrf8M4zn","spreadsheet_id":"1c_FcPTNrSJdVK8S67Jrg9cDxq6_Umie8tnt0XTQn3Hw","audit_status":"INSTRUMENT_REVIEW","planned_start":"2026-07-20T00:00:00+07:00","planned_end":"2026-07-21T00:00:00+07:00","lead_auditor":"4769c65d-0d21-4afe-b675-847b63df9c64","auditee_head":"","created_at":"2026-07-19T08:57:18+07:00","audit_code":"AUD-2026-00001","period_id":"c5cadec3-070e-469a-919b-6ff404b14afb","audit_title":"AMI NA ","audit_type":"NON_AKADEMIK","risk_level":"LOW","status":"INSTRUMENT_REVIEW","manager_user_id":"4769c65d-0d21-4afe-b675-847b63df9c64","notes":"","_created_at":"2026-07-19T08:57:18+07:00","_created_by":"admin","_updated_at":"2026-07-19T09:06:13+07:00","_updated_by":"admin","_row_version":6,"_deleted_at":"","_deleted_by":"","unit_code":"P3M","questionnaire_status":"DRAFT","questionnaire_published_at":"","spreadsheet_url":"https://docs.google.com/spreadsheets/d/1c_FcPTNrSJdVK8S67Jrg9cDxq6_Umie8tnt0XTQn3Hw/edit","audit_folder_url":"https://drive.google.com/drive/folders/1xKRMK3aqpGR9FFZ1DxohGZ4mHrf8M4zn","evidence_folder_id":"1tbpVhkSnW46xiWLr-PNC6by__mRM-lkf","print_folder_id":"1m2D7XIvuDjXKMMG3mVmJeVL0KgcJIQ57","file_status":"ACTIVE","template_version":1,"_spreadsheet_id":"1c_FcPTNrSJdVK8S67Jrg9cDxq6_Umie8tnt0XTQn3Hw","_audit_id":"25f27b13-a0b0-46a7-b5f7-064277dbaf3f"} | I24: SUCCESS | J24: 46222.379 | K24: admin | L24: 46222.379 | M24: admin | N24: 1 | Q24: admin
A25: 1685efa1-0bce-41e9-b3be-59592fa9372e | B25: 46222.38 | C25: admin | D25: WORKFLOW_START_INSTRUMENT_REVIEW | E25: AUDIT_PROGRAM | F25: 25f27b13-a0b0-46a7-b5f7-064277dbaf3f | G25: {"_sheet_row":2,"audit_id":"25f27b13-a0b0-46a7-b5f7-064277dbaf3f","audit_year":2026,"unit_id":"UNIT-P3M","unit_name":"Pusat Penelitian dan Pengabdian kepada Masyarakat","audit_file_name":"p3m_2026","audit_folder_id":"1xKRMK3aqpGR9FFZ1DxohGZ4mHrf8M4zn","spreadsheet_id":"1c_FcPTNrSJdVK8S67Jrg9cDxq6_Umie8tnt0XTQn3Hw","audit_status":"FILE_PREPARATION","planned_start":"2026-07-20T00:00:00+07:00","planned_end":"2026-07-21T00:00:00+07:00","lead_auditor":"4769c65d-0d21-4afe-b675-847b63df9c64","auditee_head":"","created_at":"2026-07-19T08:57:18+07:00","audit_code":"AUD-2026-00001","period_id":"c5cadec3-070e-469a-919b-6ff404b14afb","audit_title":"AMI NA ","audit_type":"NON_AKADEMIK","risk_level":"LOW","status":"FILE_PREPARATION","manager_user_id":"4769c65d-0d21-4afe-b675-847b63df9c64","notes":"","_created_at":"2026-07-19T08:57:18+07:00","_created_by":"admin","_updated_at":"2026-07-19T09:05:18+07:00","_updated_by":"admin","_row_version":5,"_deleted_at":"","_deleted_by":"","unit_code":"P3M","questionnaire_status":"DRAFT","questionnaire_published_at":"","spreadsheet_url":"https://docs.google.com/spreadsheets/d/1c_FcPTNrSJdVK8S67Jrg9cDxq6_Umie8tnt0XTQn3Hw/edit","audit_folder_url":"https://drive.google.com/drive/folders/1xKRMK3aqpGR9FFZ1DxohGZ4mHrf8M4zn","evidence_folder_id":"1tbpVhkSnW46xiWLr-PNC6by__mRM-lkf","print_folder_id":"1m2D7XIvuDjXKMMG3mVmJeVL0KgcJIQ57","file_status":"ACTIVE","template_version":1,"_spreadsheet_id":"1c_FcPTNrSJdVK8S67Jrg9cDxq6_Umie8tnt0XTQn3Hw","_audit_id":"25f27b13-a0b0-46a7-b5f7-064277dbaf3f"} | H25: {"_sheet_row":2,"audit_id":"25f27b13-a0b0-46a7-b5f7-064277dbaf3f","audit_year":2026,"unit_id":"UNIT-P3M","unit_name":"Pusat Penelitian dan Pengabdian kepada Masyarakat","audit_file_name":"p3m_2026","audit_folder_id":"1xKRMK3aqpGR9FFZ1DxohGZ4mHrf8M4zn","spreadsheet_id":"1c_FcPTNrSJdVK8S67Jrg9cDxq6_Umie8tnt0XTQn3Hw","audit_status":"INSTRUMENT_REVIEW","planned_start":"2026-07-20T00:00:00+07:00","planned_end":"2026-07-21T00:00:00+07:00","lead_auditor":"4769c65d-0d21-4afe-b675-847b63df9c64","auditee_head":"","created_at":"2026-07-19T08:57:18+07:00","audit_code":"AUD-2026-00001","period_id":"c5cadec3-070e-469a-919b-6ff404b14afb","audit_title":"AMI NA ","audit_type":"NON_AKADEMIK","risk_level":"LOW","status":"INSTRUMENT_REVIEW","manager_user_id":"4769c65d-0d21-4afe-b675-847b63df9c64","notes":"","_created_at":"2026-07-19T08:57:18+07:00","_created_by":"admin","_updated_at":"2026-07-19T09:06:13+07:00","_updated_by":"admin","_row_version":6,"_deleted_at":"","_deleted_by":"","unit_code":"P3M","questionnaire_status":"DRAFT","questionnaire_published_at":"","spreadsheet_url":"https://docs.google.com/spreadsheets/d/1c_FcPTNrSJdVK8S67Jrg9cDxq6_Umie8tnt0XTQn3Hw/edit","audit_folder_url":"https://drive.google.com/drive/folders/1xKRMK3aqpGR9FFZ1DxohGZ4mHrf8M4zn","evidence_folder_id":"1tbpVhkSnW46xiWLr-PNC6by__mRM-lkf","print_folder_id":"1m2D7XIvuDjXKMMG3mVmJeVL0KgcJIQ57","file_status":"ACTIVE","template_version":1,"_spreadsheet_id":"1c_FcPTNrSJdVK8S67Jrg9cDxq6_Umie8tnt0XTQn3Hw","_audit_id":"25f27b13-a0b0-46a7-b5f7-064277dbaf3f"} | I25: SUCCESS | J25: 46222.38 | K25: admin | L25: 46222.38 | M25: admin | N25: 1 | Q25: admin
A26: 6362f234-01de-4a97-9367-ddc6d7032eee | B26: 46222.381 | C26: admin | D26: QUESTION_REVIEW_SAVED | E26: AUDIT_PROGRAM | F26: 25f27b13-a0b0-46a7-b5f7-064277dbaf3f | H26: {"count":66} | I26: SUCCESS | J26: 46222.381 | K26: admin | L26: 46222.381 | M26: admin | N26: 1 | Q26: admin
A27: ca22bdf6-e326-48f7-9d96-7ff2c4dd6a26 | B27: 46222.381 | C27: admin | D27: CREATE | E27: APPROVALS | F27: 87deff13-a804-4dac-8117-d8d8dac371ff | H27: {"_sheet_row":2,"approval_id":"87deff13-a804-4dac-8117-d8d8dac371ff","entity_type":"AUDIT_QUESTION_SET","entity_id":"25f27b13-a0b0-46a7-b5f7-064277dbaf3f","approval_step":"QUESTION_PUBLICATION","approver_user_id":"c73c3a59-8171-440d-b344-a86905adf9ae","decision":"AUTO_APPROVED_DEFAULT","decision_note":"tidak ada perubahan","decided_at":"2026-07-19T09:08:55+07:00","audit_id":"25f27b13-a0b0-46a7-b5f7-064277dbaf3f","_created_at":"2026-07-19T09:08:55+07:00","_created_by":"admin","_updated_at":"2026-07-19T09:08:55+07:00","_updated_by":"admin","_row_version":1,"_deleted_at":"","_deleted_by":"","_spreadsheet_id":"1c_FcPTNrSJdVK8S67Jrg9cDxq6_Umie8tnt0XTQn3Hw","_audit_id":"25f27b13-a0b0-46a7-b5f7-064277dbaf3f"} | I27: SUCCESS | J27: 46222.381 | K27: admin | L27: 46222.381 | M27: admin | N27: 1 | Q27: admin
A28: ea819acf-078e-4af9-b22a-14d038164e08 | B28: 46222.381 | C28: admin | D28: QUESTIONNAIRE_PUBLISHED | E28: AUDIT_PROGRAM | F28: 25f27b13-a0b0-46a7-b5f7-064277dbaf3f | H28: {"count":66} | I28: SUCCESS | J28: 46222.381 | K28: admin | L28: 46222.381 | M28: admin | N28: 1 | Q28: admin
A29: 9b20f53a-9622-4124-bf53-417d5040ba2f | B29: 46222.383 | C29: p3m-polbeng | D29: LOGIN | E29: USER | F29: cfb22fc1-09e4-486e-a3aa-52ff8c9534a5 | H29: {"username":"p3m-polbeng"} | I29: SUCCESS | J29: 46222.383 | K29: p3m-polbeng | L29: 46222.383 | M29: p3m-polbeng | N29: 1 | Q29: p3m-polbeng

Sheet 01_CONFIG
A1: config_key | B1: config_value | C1: data_type | D1: scope | E1: description | F1: required | G1: editable | H1: updated_at
A2: APP_NAME | B2: SAMI-NONAK Polbeng | C2: TEXT | D2: SYSTEM | E2: Nama aplikasi | F2: TRUE | G2: TRUE
A3: APP_CODE | B3: SAMI_NONAK | C3: TEXT | D3: SYSTEM | E3: Kode aplikasi | F3: TRUE | G3: FALSE
A4: APP_VERSION | B4: 1.2.0 | C4: TEXT | D4: SYSTEM | E4: Versi aplikasi | F4: TRUE | G4: TRUE | H4: 46222.353
A5: SYSTEM_MODE | B5: DEVELOPMENT | C5: LOOKUP:SYSTEM_MODE | D5: SYSTEM | E5: Mode DEVELOPMENT/PRODUCTION | F5: TRUE | G5: TRUE
A6: SYSTEM_SPREADSHEET_ID | B6: 1J_32KxE3BsaXJVNxAk54A7XsLVvuV5PcV5UVaYZl68A | C6: TEXT | D6: SYSTEM | E6: ID file Google Sheet Sistem; diisi fungsi initSystem() | F6: TRUE | G6: FALSE | H6: 46222.353
A7: TRANSACTION_STORAGE_MODE | B7: PER_UNIT_YEAR_SPREADSHEET | C7: TEXT | D7: DATABASE | E7: Setiap unit dan tahun audit mempunyai Google Sheet transaksi tersendiri | F7: TRUE | G7: FALSE | H7: 46222.352
A8: DEFAULT_AUDIT_PERIOD | B8: 2026 | C8: TEXT | D8: AUDIT | E8: Periode audit default | F8: TRUE | G8: TRUE
A9: TIMEZONE | B9: Asia/Jakarta | C9: TEXT | D9: SYSTEM | E9: Zona waktu aplikasi | F9: TRUE | G9: TRUE
A10: LOCALE | B10: id_ID | C10: TEXT | D10: SYSTEM | E10: Lokal aplikasi | F10: TRUE | G10: TRUE
A11: DATE_FORMAT | B11: dd/MM/yyyy | C11: TEXT | D11: SYSTEM | E11: Format tanggal tampilan | F11: TRUE | G11: TRUE
A12: DATETIME_FORMAT | B12: dd/MM/yyyy HH:mm:ss | C12: TEXT | D12: SYSTEM | E12: Format waktu tampilan | F12: TRUE | G12: TRUE
A13: ACTIVE_PROCESS_STANDARD | B13: ISO9001_2015_A1_2024 | C13: TEXT | D13: STANDARD | E13: ISO 9001:2015 digunakan untuk pendekatan proses dan pengendalian proses bisnis | F13: TRUE | G13: TRUE | H13: 2026-07-19
A14: ACTIVE_ORG_VERSION | B14: OTK_POLBENG_2022 | C14: TEXT | D14: ORGANIZATION | E14: Struktur dan tupoksi unit berdasarkan OTK Polbeng yang berlaku | F14: TRUE | G14: TRUE | H14: 2026-07-19
A15: MAX_UPLOAD_MB | B15: 10 | C15: NUMBER | D15: EVIDENCE | E15: Batas ukuran satu file | F15: TRUE | G15: TRUE
A16: EVIDENCE_STORAGE_MODE | B16: GOOGLE_DRIVE | C16: LOOKUP:STORAGE_MODE | D16: EVIDENCE | E16: Metode penyimpanan bukti | F16: TRUE | G16: TRUE
A17: EVIDENCE_ROOT_FOLDER_ID | B17: 1bavSo7fYdE8p4rrMnGVAsGYmjLtWHCSs | C17: TEXT | D17: EVIDENCE | E17: Folder induk bukti di Google Drive | F17: TRUE | G17: TRUE | H17: 46222.353
A18: ENABLE_EMAIL_NOTIFICATION | B18: TRUE | C18: BOOLEAN | D18: NOTIFICATION | E18: Aktifkan email notifikasi | F18: TRUE | G18: TRUE
A19: ENABLE_AUDIT_LOG | B19: TRUE | C19: BOOLEAN | D19: SECURITY | E19: Aktifkan log aktivitas | F19: TRUE | G19: TRUE
A20: ALLOW_PUBLIC_ACCESS | B20: FALSE | C20: BOOLEAN | D20: SECURITY | E20: Harus FALSE untuk aplikasi institusi | F20: TRUE | G20: FALSE
A21: DEFAULT_PAGE_SIZE | B21: 25 | C21: NUMBER | D21: UI | E21: Jumlah baris per halaman | F21: TRUE | G21: TRUE
A22: CACHE_SECONDS | B22: 300 | C22: NUMBER | D22: PERFORMANCE | E22: Durasi cache master data | F22: TRUE | G22: TRUE
A23: WEBAPP_URL | C23: URL | D23: SYSTEM | E23: URL deployment web app | F23: FALSE | G23: TRUE
A24: AUTH_MODE | B24: USERNAME_PASSWORD | C24: TEXT | D24: SECURITY | E24: Login aplikasi memakai username dan password yang dikelola pada Sheet Sistem | F24: TRUE | G24: FALSE | H24: 2026-07-19
A25: USER_ACCOUNT_SOURCE | B25: SYSTEM_SHEET | C25: TEXT | D25: SECURITY | E25: Akun, role, unit, password, dan status aktif dikelola terpusat; bukan transaksi audit | F25: TRUE | G25: FALSE | H25: 2026-07-19
A26: SYSTEM_SHEET_STORES_TRANSACTIONS | B26: FALSE | C26: BOOLEAN | D26: DATABASE | E26: Sheet Sistem dilarang menyimpan jawaban auditee, kertas kerja, temuan, tindak lanjut, atau verifikasi | F26: TRUE | G26: FALSE | H26: 46222.352
A27: ACTIVE_AUDIT_REGULATION | B27: PMPT_39_2025 | C27: TEXT | D27: STANDARD | E27: Kriteria mutu mengacu Permendiktisaintek 39/2025 dan standar internal Polbeng yang diturunkan darinya | F27: TRUE | G27: TRUE | H27: 2026-07-19
A28: AUDIT_FILE_NAMING_PATTERN | B28: {unit_slug}_{audit_year} | C28: TEXT | D28: DATABASE | E28: Nama Google Sheet transaksi audit | F28: TRUE | G28: FALSE | H28: 2026-07-19
A29: AUDIT_FOLDER_NAMING_PATTERN | B29: {unit_slug}_{audit_year} | C29: TEXT | D29: EVIDENCE | E29: Nama folder audit unit dan tahun | F29: TRUE | G29: FALSE | H29: 2026-07-19
A30: EVIDENCE_SUBFOLDER_NAME | B30: EVIDENCE | C30: TEXT | D30: EVIDENCE | E30: Subfolder lampiran fisik | F30: TRUE | G30: TRUE | H30: 2026-07-19
A31: PRINT_SUBFOLDER_NAME | B31: CETAK | C31: TEXT | D31: REPORT | E31: Subfolder versi cetak PDF | F31: TRUE | G31: TRUE | H31: 2026-07-19
A32: CREATE_ONE_FILE_PER_UNIT_YEAR | B32: TRUE | C32: BOOLEAN | D32: DATABASE | E32: Satu Google Sheet transaksi untuk satu unit pada satu tahun audit | F32: TRUE | G32: FALSE | H32: 2026-07-19
A33: AUDITOR_UNCHANGED_PUBLISH_DIRECTLY | B33: TRUE | C33: BOOLEAN | D33: WORKFLOW | E33: Instrumen tanpa perubahan auditor langsung diterbitkan kepada auditee | F33: TRUE | G33: TRUE | H33: 2026-07-19
A34: AUDITOR_CHANGED_REQUIRES_APPROVAL | B34: TRUE | C34: BOOLEAN | D34: WORKFLOW | E34: Instrumen yang diubah auditor wajib disetujui Verifikator/P4MP | F34: TRUE | G34: TRUE | H34: 2026-07-19
A35: INSTRUMENT_APPROVER_ROLES | B35: P4MP_VERIFIKATOR|VERIFIKATOR|ADMIN_MUTU | C35: MULTI_TEXT | D35: WORKFLOW | E35: Role yang menyetujui perubahan instrumen | F35: TRUE | G35: TRUE | H35: 2026-07-19
A36: PRINT_FORMAT | B36: PDF | C36: TEXT | D36: REPORT | E36: Format versi cetak audit | F36: TRUE | G36: FALSE | H36: 2026-07-19
A37: AUDIT_FILE_TEMPLATE_VERSION | B37: 1.0 | C37: TEXT | D37: DATABASE | E37: Versi struktur file transaksi unit-tahun | F37: TRUE | G37: TRUE | H37: 2026-07-19
A38: INTERNAL_STANDARD_VERSION | B38: 2026-D1 | C38: TEXT | D38: STANDARD | E38: Versi rancangan standar internal nonakademik | F38: TRUE | G38: TRUE | H38: 2026-07-19
A39: INTERNAL_STANDARD_STATUS | B39: PROPOSED_FOR_FORMALIZATION | C39: TEXT | D39: STANDARD | E39: Status hukum rancangan standar internal | F39: TRUE | G39: FALSE | H39: 2026-07-19
A40: AUDIT_MATRIX_VERSION | B40: 2026-D1 | C40: TEXT | D40: AUDIT | E40: Versi matriks tupoksi-standar-regulasi-ISO-pertanyaan | F40: TRUE | G40: TRUE | H40: 46222.352

Sheet 02_AUDIT_FILE_REGISTRY
A1: audit_file_id | B1: audit_year | C1: unit_id | D1: unit_name | E1: audit_file_name | F1: spreadsheet_id | G1: spreadsheet_url | H1: audit_folder_id | I1: audit_folder_url | J1: evidence_folder_id | K1: print_folder_id | L1: file_status | M1: template_version | N1: created_at | O1: updated_at | P1: notes
A2: 25f27b13-a0b0-46a7-b5f7-064277dbaf3f | B2: 2026 | C2: UNIT-P3M | D2: Pusat Penelitian dan Pengabdian kepada Masyarakat | E2: p3m_2026 | F2: 1c_FcPTNrSJdVK8S67Jrg9cDxq6_Umie8tnt0XTQn3Hw | G2: https://docs.google.com/spreadsheets/d/1c_FcPTNrSJdVK8S67Jrg9cDxq6_Umie8tnt0XTQn3Hw/edit | H2: 1xKRMK3aqpGR9FFZ1DxohGZ4mHrf8M4zn | I2: https://drive.google.com/drive/folders/1xKRMK3aqpGR9FFZ1DxohGZ4mHrf8M4zn | J2: 1tbpVhkSnW46xiWLr-PNC6by__mRM-lkf | K2: 1m2D7XIvuDjXKMMG3mVmJeVL0KgcJIQ57 | L2: ACTIVE | M2: 1 | N2: 46222.373 | O2: 46222.381

Sheet 03_AUDIT_SHEET_TEMPLATE
A1: template_id | B1: sheet_code | C1: sheet_name | D1: sheet_title | E1: purpose | F1: owner_role | G1: write_roles | H1: read_roles | I1: print_source | J1: display_order | K1: active | L1: notes
A2: SHT-00 | B2: IDENTITY | C2: 00_IDENTITAS | D2: Identitas Audit | E2: Metadata audit, unit, tahun, tim, jadwal, dan status file | F2: ADMIN_MUTU | G2: ADMIN_MUTU|SEKRETARIAT | H2: * | I2: YES | J2: 0 | K2: TRUE | L2: Dibuat otomatis saat rencana audit disahkan
A3: SHT-01 | B3: INSTRUMENT | C3: 01_INSTRUMEN | D3: Instrumen Audit | E3: Salinan pertanyaan default, hasil telaah auditor, persetujuan P4MP, dan pertanyaan terbit | F3: KETUA_AUDITOR | G3: AUDITOR|KETUA_AUDITOR|VERIFIKATOR|P4MP_VERIFIKATOR|ADMIN_MUTU | H3: AUDITOR|KETUA_AUDITOR|VERIFIKATOR|P4MP_VERIFIKATOR|ADMIN_MUTU|AUDITEE | I3: YES | J3: 1 | K3: TRUE | L3: Auditee hanya melihat pertanyaan berstatus PUBLISHED
A4: SHT-02 | B4: AUDITEE_RESPONSE | C4: 02_JAWABAN_AUDITEE | D4: Jawaban Auditee | E4: Jawaban, penilaian mandiri, uraian pelaksanaan, kendala, dan pengesahan unit | F4: AUDITEE | G4: AUDITEE|KEPALA_UNIT | H4: AUDITEE|KEPALA_UNIT|AUDITOR|KETUA_AUDITOR|ADMIN_MUTU | I4: YES | J4: 2 | K4: TRUE | L4: Seluruh transaksi auditee berada di file audit unit-tahun
A5: SHT-03 | B5: EVIDENCE | C5: 03_BUKTI | D5: Register Bukti | E5: Metadata file bukti dan tautan Google Drive | F5: AUDITEE | G5: AUDITEE|KEPALA_UNIT|AUDITOR | H5: AUDITEE|KEPALA_UNIT|AUDITOR|KETUA_AUDITOR|VERIFIKATOR|ADMIN_MUTU | I5: YES | J5: 3 | K5: TRUE | L5: Berkas fisik disimpan di subfolder EVIDENCE
A6: SHT-04 | B6: WORKPAPER | C6: 04_KERTAS_KERJA | D6: Kertas Kerja Auditor | E6: Sampel, wawancara, bukti objektif, analisis, dan status kesesuaian | F6: AUDITOR | G6: AUDITOR|KETUA_AUDITOR | H6: AUDITOR|KETUA_AUDITOR|VERIFIKATOR|ADMIN_MUTU | I6: NO | J6: 4 | K6: TRUE | L6: Tidak dapat diedit oleh auditee
A7: SHT-05 | B7: FINDING | C7: 05_TEMUAN | D7: Temuan Audit | E7: Kriteria, kondisi, bukti objektif, kesenjangan, risiko, dan klasifikasi temuan | F7: KETUA_AUDITOR | G7: AUDITOR|KETUA_AUDITOR | H7: AUDITOR|KETUA_AUDITOR|AUDITEE|KEPALA_UNIT|VERIFIKATOR|ADMIN_MUTU | I7: YES | J7: 5 | K7: TRUE | L7: Kriteria harus memuat regulasi mutu dan klausul ISO proses
A8: SHT-06 | B8: FOLLOW_UP | C8: 06_TINDAK_LANJUT | D8: Tindak Lanjut | E8: Koreksi, akar penyebab, tindakan korektif, PIC, target, kemajuan, dan bukti | F8: AUDITEE | G8: AUDITEE|KEPALA_UNIT | H8: AUDITEE|KEPALA_UNIT|AUDITOR|KETUA_AUDITOR|VERIFIKATOR|ADMIN_MUTU | I8: YES | J8: 6 | K8: TRUE | L8: Data tindak lanjut berada pada file audit yang sama
A9: SHT-07 | B9: VERIFICATION | C9: 07_VERIFIKASI | D9: Verifikasi Efektivitas | E9: Verifikasi pelaksanaan, efektivitas, dan keputusan penutupan | F9: VERIFIKATOR | G9: VERIFIKATOR|P4MP_VERIFIKATOR|ADMIN_MUTU | H9: VERIFIKATOR|P4MP_VERIFIKATOR|AUDITOR|KETUA_AUDITOR|AUDITEE|KEPALA_UNIT|ADMIN_MUTU | I9: YES | J9: 7 | K9: TRUE | L9: Efektivitas dibedakan dari sekadar selesai dilaksanakan
A10: SHT-08 | B10: APPROVAL | C10: 08_PERSETUJUAN | D10: Persetujuan | E10: Riwayat keputusan auditor, P4MP, kepala unit, dan pimpinan | F10: SYSTEM | G10: SYSTEM | H10: * | I10: NO | J10: 8 | K10: TRUE | L10: Ditulis oleh workflow, bukan isian bebas
A11: SHT-09 | B11: LOG | C11: 09_LOG | D11: Log Aktivitas | E11: Jejak perubahan seluruh transaksi audit unit-tahun | F11: SYSTEM | G11: SYSTEM | H11: SUPER_ADMIN|ADMIN_MUTU|SPI_OBSERVER | I11: NO | J11: 9 | K11: TRUE | L11: Tidak disimpan pada Sheet Sistem
A12: SHT-10 | B12: SUMMARY | C12: 10_REKAP | D12: Rekap Audit | E12: Ringkasan capaian, temuan, tindak lanjut, dan sumber cetak laporan | F12: SYSTEM | G12: SYSTEM | H12: * | I12: YES | J12: 10 | K12: TRUE | L12: Dihitung dari tab transaksi dalam file audit
A13: SHT-11 | B13: PRINT_REGISTRY | C13: 11_CETAK_REGISTER | D13: Register Dokumen Cetak | E13: Versi, status, ID file, tautan, pembentuk, dan pengesah PDF | F13: SYSTEM | G13: SYSTEM | H13: SUPER_ADMIN|ADMIN_MUTU|MANAJER_AUDIT|KETUA_AUDITOR|PIMPINAN|SEKRETARIAT | I13: NO | J13: 11 | K13: TRUE | L13: PDF fisik berada di folder CETAK

Sheet 04_AUDIT_FIELD_TEMPLATE
A1: sheet_code | B1: field_name | C1: label | D1: data_type | E1: required | F1: editable_roles | G1: source | H1: lookup_key | I1: display_order | J1: active | K1: notes
A2: IDENTITY | B2: audit_id | C2: ID Audit | D2: UUID | E2: TRUE | F2: SYSTEM | G2: SYSTEM | I2: 1 | J2: TRUE | K2: Primary key audit
A3: IDENTITY | B3: audit_year | C3: Tahun Audit | D3: YEAR | E3: TRUE | F3: ADMIN_MUTU | G3: 01_CONFIG | I3: 2 | J3: TRUE
A4: IDENTITY | B4: unit_id | C4: ID Unit | D4: LOOKUP | E4: TRUE | F4: ADMIN_MUTU | G4: 12_UNITS | H4: UNIT | I4: 3 | J4: TRUE
A5: IDENTITY | B5: unit_name | C5: Nama Unit | D5: TEXT | E5: TRUE | F5: SYSTEM | G5: 12_UNITS | I5: 4 | J5: TRUE
A6: IDENTITY | B6: audit_file_name | C6: Nama File Audit | D6: TEXT | E6: TRUE | F6: SYSTEM | G6: 26_FOLDER_RULES | I6: 5 | J6: TRUE | K6: Format {unit_slug}_{audit_year}
A7: IDENTITY | B7: audit_folder_id | C7: ID Folder Audit | D7: TEXT | E7: TRUE | F7: SYSTEM | G7: DRIVE | I7: 6 | J7: TRUE
A8: IDENTITY | B8: spreadsheet_id | C8: ID Google Sheet Audit | D8: TEXT | E8: TRUE | F8: SYSTEM | G8: DRIVE | I8: 7 | J8: TRUE
A9: IDENTITY | B9: audit_status | C9: Status Audit | D9: LOOKUP | E9: TRUE | F9: ADMIN_MUTU|MANAJER_AUDIT | G9: 21_LOOKUPS | H9: AUDIT_STATUS | I9: 8 | J9: TRUE
A10: IDENTITY | B10: planned_start | C10: Rencana Mulai | D10: DATE | E10: TRUE | F10: ADMIN_MUTU | G10: USER_INPUT | I10: 9 | J10: TRUE
A11: IDENTITY | B11: planned_end | C11: Rencana Selesai | D11: DATE | E11: TRUE | F11: ADMIN_MUTU | G11: USER_INPUT | I11: 10 | J11: TRUE
A12: IDENTITY | B12: lead_auditor | C12: Ketua Auditor | D12: LOOKUP | E12: TRUE | F12: ADMIN_MUTU | G12: SYSTEM_USERS | H12: USER | I12: 11 | J12: TRUE
A13: IDENTITY | B13: auditee_head | C13: Kepala Unit | D13: LOOKUP | E13: TRUE | F13: ADMIN_MUTU | G13: SYSTEM_USERS | H13: USER | I13: 12 | J13: TRUE
A14: IDENTITY | B14: created_at | C14: Dibuat Pada | D14: DATETIME | E14: TRUE | F14: SYSTEM | G14: SYSTEM | I14: 13 | J14: TRUE
A15: INSTRUMENT | B15: audit_question_id | C15: ID Pertanyaan Audit | D15: UUID | E15: TRUE | F15: SYSTEM | G15: SYSTEM | I15: 1 | J15: TRUE
A16: INSTRUMENT | B16: source_question_id | C16: ID Pertanyaan Default | D16: LOOKUP | E16: TRUE | F16: SYSTEM | G16: 17_QUESTION_BANK | H16: QUESTION | I16: 2 | J16: TRUE
A17: INSTRUMENT | B17: question_code | C17: Kode Pertanyaan | D17: TEXT | E17: TRUE | F17: SYSTEM | G17: 17_QUESTION_BANK | I17: 3 | J17: TRUE
A18: INSTRUMENT | B18: requirement_code | C18: Kode Standar/Kriteria | D18: MULTI_LOOKUP | E18: TRUE | F18: SYSTEM | G18: 24_Q_REQUIREMENT_MAP | H18: REQUIREMENT | I18: 4 | J18: TRUE
A19: INSTRUMENT | B19: regulation_ref | C19: Rujukan Regulasi | D19: TEXT | E19: TRUE | F19: SYSTEM | G19: 16_REQUIREMENTS | I19: 5 | J19: TRUE | K19: Permendiktisaintek 39/2025 atau standar internal turunannya
A20: INSTRUMENT | B20: iso_clause | C20: Klausul ISO Proses | D20: TEXT | E20: TRUE | F20: SYSTEM | G20: 15_ISO_CLAUSES | I20: 6 | J20: TRUE
A21: INSTRUMENT | B21: unit_function_id | C21: Tupoksi Unit | D21: LOOKUP | E21: TRUE | F21: SYSTEM | G21: 13_UNIT_FUNCTIONS | H21: UNIT_FUNCTION | I21: 7 | J21: TRUE
A22: INSTRUMENT | B22: default_question | C22: Pertanyaan Default | D22: LONGTEXT | E22: TRUE | F22: SYSTEM | G22: 17_QUESTION_BANK | I22: 8 | J22: TRUE
A23: INSTRUMENT | B23: auditor_question | C23: Pertanyaan Hasil Telaah Auditor | D23: LONGTEXT | E23: TRUE | F23: AUDITOR|KETUA_AUDITOR | G23: USER_INPUT | I23: 9 | J23: TRUE
A24: INSTRUMENT | B24: change_flag | C24: Ada Perubahan | D24: BOOLEAN | E24: TRUE | F24: SYSTEM | G24: SYSTEM | I24: 10 | J24: TRUE | K24: Dihitung dengan membandingkan pertanyaan default dan hasil telaah
A25: INSTRUMENT | B25: review_status | C25: Status Review | D25: LOOKUP | E25: TRUE | F25: SYSTEM | G25: 21_LOOKUPS | H25: INSTRUMENT_STATUS | I25: 11 | J25: TRUE
A26: INSTRUMENT | B26: auditor_note | C26: Catatan Auditor | D26: LONGTEXT | E26: FALSE | F26: AUDITOR|KETUA_AUDITOR | G26: USER_INPUT | I26: 12 | J26: TRUE
A27: INSTRUMENT | B27: verifier_note | C27: Catatan Verifikator/P4MP | D27: LONGTEXT | E27: FALSE | F27: VERIFIKATOR|P4MP_VERIFIKATOR | G27: USER_INPUT | I27: 13 | J27: TRUE
A28: INSTRUMENT | B28: published_question | C28: Pertanyaan Terbit | D28: LONGTEXT | E28: FALSE | F28: SYSTEM | G28: SYSTEM | I28: 14 | J28: TRUE | K28: Hanya nilai ini ditampilkan ke auditee
A29: INSTRUMENT | B29: evidence_hint | C29: Bukti yang Diharapkan | D29: LONGTEXT | E29: FALSE | F29: AUDITOR|KETUA_AUDITOR | G29: 17_QUESTION_BANK | I29: 15 | J29: TRUE
A30: INSTRUMENT | B30: risk_level | C30: Tingkat Risiko | D30: LOOKUP | E30: TRUE | F30: AUDITOR|KETUA_AUDITOR | G30: 17_QUESTION_BANK | H30: RISK_LEVEL | I30: 16 | J30: TRUE
A31: INSTRUMENT | B31: weight | C31: Bobot | D31: NUMBER | E31: TRUE | F31: AUDITOR|KETUA_AUDITOR | G31: 17_QUESTION_BANK | I31: 17 | J31: TRUE
A32: INSTRUMENT | B32: mandatory | C32: Wajib | D32: BOOLEAN | E32: TRUE | F32: AUDITOR|KETUA_AUDITOR | G32: 17_QUESTION_BANK | I32: 18 | J32: TRUE
A33: INSTRUMENT | B33: sort_order | C33: Urutan | D33: NUMBER | E33: TRUE | F33: AUDITOR|KETUA_AUDITOR | G33: 17_QUESTION_BANK | I33: 19 | J33: TRUE
A34: AUDITEE_RESPONSE | B34: response_id | C34: ID Jawaban | D34: UUID | E34: TRUE | F34: SYSTEM | G34: SYSTEM | I34: 1 | J34: TRUE
A35: AUDITEE_RESPONSE | B35: audit_question_id | C35: ID Pertanyaan Audit | D35: LOOKUP | E35: TRUE | F35: SYSTEM | G35: 01_INSTRUMEN | H35: AUDIT_QUESTION | I35: 2 | J35: TRUE
A36: AUDITEE_RESPONSE | B36: published_question | C36: Pertanyaan | D36: LONGTEXT | E36: TRUE | F36: SYSTEM | G36: 01_INSTRUMEN | I36: 3 | J36: TRUE
A37: AUDITEE_RESPONSE | B37: self_score | C37: Skor Penilaian Mandiri | D37: NUMBER | E37: FALSE | F37: AUDITEE|KEPALA_UNIT | G37: USER_INPUT | I37: 4 | J37: TRUE
A38: AUDITEE_RESPONSE | B38: implementation_description | C38: Uraian Pelaksanaan | D38: LONGTEXT | E38: TRUE | F38: AUDITEE|KEPALA_UNIT | G38: USER_INPUT | I38: 5 | J38: TRUE
A39: AUDITEE_RESPONSE | B39: evidence_summary | C39: Ringkasan Bukti | D39: LONGTEXT | E39: FALSE | F39: AUDITEE|KEPALA_UNIT | G39: USER_INPUT | I39: 6 | J39: TRUE
A40: AUDITEE_RESPONSE | B40: constraint_note | C40: Kendala | D40: LONGTEXT | E40: FALSE | F40: AUDITEE|KEPALA_UNIT | G40: USER_INPUT | I40: 7 | J40: TRUE
...

Sheet 05_ROLES
A1: role_code | B1: role_name | C1: role_level | D1: unit_restricted | E1: description | F1: active
A2: SUPER_ADMIN | B2: Super Administrator | C2: 100 | D2: FALSE | E2: Konfigurasi penuh sistem dan database | F2: TRUE
A3: ADMIN_MUTU | B3: Administrator Mutu | C3: 90 | D3: FALSE | E3: Mengelola master standar, instrumen, program audit, dan laporan | F3: TRUE
A4: MANAJER_AUDIT | B4: Manajer Program Audit | C4: 80 | D4: FALSE | E4: Menetapkan program, ruang lingkup, tim, dan persetujuan laporan | F4: TRUE
A5: KETUA_AUDITOR | B5: Ketua Auditor | C5: 70 | D5: FALSE | E5: Mengendalikan pelaksanaan audit dan reviu temuan | F5: TRUE
A6: AUDITOR | B6: Auditor | C6: 60 | D6: FALSE | E6: Desk review, kertas kerja, pengujian, dan temuan | F6: TRUE
A7: AUDITEE | B7: Auditee/PIC | C7: 40 | D7: TRUE | E7: Mengisi penilaian mandiri dan tindak lanjut | F7: TRUE
A8: KEPALA_UNIT | B8: Kepala Unit | C8: 50 | D8: TRUE | E8: Mengesahkan jawaban unit dan rencana tindakan | F8: TRUE
A9: VERIFIKATOR | B9: Verifikator | C9: 65 | D9: FALSE | E9: Memeriksa pelaksanaan dan efektivitas tindakan | F9: TRUE
A10: PIMPINAN | B10: Pimpinan | C10: 75 | D10: FALSE | E10: Dashboard, persetujuan, dan keputusan tinjauan manajemen | F10: TRUE
A11: SPI_OBSERVER | B11: SPI/Observer | C11: 55 | D11: FALSE | E11: Akses pemantauan dan analisis pengawasan nonakademik | F11: TRUE
A12: SEKRETARIAT | B12: Sekretariat Audit | C12: 45 | D12: FALSE | E12: Administrasi jadwal, surat tugas, berita acara, dan notifikasi | F12: TRUE
